Workbook

Sheet Buyer Wise OTT Hit Rate
C4: SQ Biricina OTT Vs Actual RFD Status
C5: For the month of Oct' 2026
S6: Report Date | U6: 46258
C7: 46324 | I7: =C7+1 | M7: =C7 | S7: Report Date | U7: 46308
C8: Buyer's | D8: =TODAY() | I8: MTD | P8: Recovered & RFD done quantity | Q8: Actual RFD Balance | S8: Sign off line plan Qty | T8: MTD RFD Qty | U8: To be delivered qty | W8: =SUBTOTAL(9,W10:W20)
D9: Plan | E9: Actual | F9: Deviation | G9: % | I9: Plan | J9: ="ACTUAL UPTO "&TEXT(TODAY(),"mmmm d, yyyy") | K9: Plan Vs Actual % | L9: MTD Deviation | M9: Advance RFD | N9: Advance %
C10: Hema | D10: =SUMIFS('Fab Plan-Final'!L:L,'Fab Plan-Final'!S:S,'Buyer Wise OTT Hit Rate'!$C$7,'Fab Plan-Final'!A:A,'Buyer Wise OTT Hit Rate'!C10) | E10: =SUMIFS('Fab Plan-Final'!M:M,'Fab Plan-Final'!S:S,'Buyer Wise OTT Hit Rate'!$C$7,'Fab Plan-Final'!A:A,'Buyer Wise OTT Hit Rate'!C10) | F10: =E10-D10 | G10: =IFERROR((E10/D10),"") | I10: =SUMIFS('Fab Plan-Final'!L:L, 'Fab Plan-Final'!S:S,"<"&$I$7, 'Fab Plan-Final'!A:A,'Buyer Wise OTT Hit Rate'!C10) | J10: =SUMIFS('Fab Plan-Final'!M:M, 'Fab Plan-Final'!S:S,"<"&$I$7, 'Fab Plan-Final'!A:A,'Buyer Wise OTT Hit Rate'!C10) | K10: =IFERROR(J10/I10,"") | L10: =J10-I10 | M10: =SUMIFS('Fab Plan-Final'!M:M, 'Fab Plan-Final'!S:S,">"&$M$7, 'Fab Plan-Final'!A:A,'Buyer Wise OTT Hit Rate'!C10) | N10: =IFERROR((J10+M10)/I10,"") | P10: =SUMIFS('Fab Plan-Final'!O:O, 'Fab Plan-Final'!S:S,"<"&$I$7, 'Fab Plan-Final'!A:A,'Buyer Wise OTT Hit Rate'!C10) | Q10: =(J10+P10)-I10 | S10: =SUMIFS('Fab Plan-Final'!L:L,'Fab Plan-Final'!A:A,'Buyer Wise OTT Hit Rate'!C10) | T10: =J10+M10+P10 | U10: =S10-T10 | V10: 18549.676 | W10: =V10-M10
C11: M & S - T33 | D11: =SUMIFS('Fab Plan-Final'!L:L,'Fab Plan-Final'!S:S,'Buyer Wise OTT Hit Rate'!$C$7,'Fab Plan-Final'!A:A,'Buyer Wise OTT Hit Rate'!C11) | E11: =SUMIFS('Fab Plan-Final'!M:M,'Fab Plan-Final'!S:S,'Buyer Wise OTT Hit Rate'!$C$7,'Fab Plan-Final'!A:A,'Buyer Wise OTT Hit Rate'!C11) | F11: =E11-D11 | G11: =IFERROR((E11/D11),"") | I11: =SUMIFS('Fab Plan-Final'!L:L, 'Fab Plan-Final'!S:S,"<"&$I$7, 'Fab Plan-Final'!A:A,'Buyer Wise OTT Hit Rate'!C11) | J11: =SUMIFS('Fab Plan-Final'!M:M, 'Fab Plan-Final'!S:S,"<"&$I$7, 'Fab Plan-Final'!A:A,'Buyer Wise OTT Hit Rate'!C11) | K11: =IFERROR(J11/I11,"") | L11: =J11-I11 | M11: =SUMIFS('Fab Plan-Final'!M:M, 'Fab Plan-Final'!S:S,">"&$M$7, 'Fab Plan-Final'!A:A,'Buyer Wise OTT Hit Rate'!C11) | N11: =IFERROR((J11+M11)/I11,"") | P11: =SUMIFS('Fab Plan-Final'!O:O, 'Fab Plan-Final'!S:S,"<"&$I$7, 'Fab Plan-Final'!A:A,'Buyer Wise OTT Hit Rate'!C11) | Q11: =(J11+P11)-I11 | S11: =SUMIFS('Fab Plan-Final'!L:L,'Fab Plan-Final'!A:A,'Buyer Wise OTT Hit Rate'!C11) | T11: =J11+M11+P11 | U11: =S11-T11 | V11: 26775.578 | W11: =V11-M11
C12: Tesco | D12: =SUMIFS('Fab Plan-Final'!L:L,'Fab Plan-Final'!S:S,'Buyer Wise OTT Hit Rate'!$C$7,'Fab Plan-Final'!A:A,'Buyer Wise OTT Hit Rate'!C12) | E12: =SUMIFS('Fab Plan-Final'!M:M,'Fab Plan-Final'!S:S,'Buyer Wise OTT Hit Rate'!$C$7,'Fab Plan-Final'!A:A,'Buyer Wise OTT Hit Rate'!C12) | F12: =E12-D12 | G12: =IFERROR((E12/D12),"") | I12: =SUMIFS('Fab Plan-Final'!L:L, 'Fab Plan-Final'!S:S,"<"&$I$7, 'Fab Plan-Final'!A:A,'Buyer Wise OTT Hit Rate'!C12) | J12: =SUMIFS('Fab Plan-Final'!M:M, 'Fab Plan-Final'!S:S,"<"&$I$7, 'Fab Plan-Final'!A:A,'Buyer Wise OTT Hit Rate'!C12) | K12: =IFERROR(J12/I12,"") | L12: =J12-I12 -> 0 | M12: =SUMIFS('Fab Plan-Final'!M:M, 'Fab Plan-Final'!S:S,">"&$M$7, 'Fab Plan-Final'!A:A,'Buyer Wise OTT Hit Rate'!C12) | N12: =IFERROR((J12+M12)/I12,"") | P12: =SUMIFS('Fab Plan-Final'!O:O, 'Fab Plan-Final'!S:S,"<"&$I$7, 'Fab Plan-Final'!A:A,'Buyer Wise OTT Hit Rate'!C12) | Q12: =(J12+P12)-I12 | S12: =SUMIFS('Fab Plan-Final'!L:L,'Fab Plan-Final'!A:A,'Buyer Wise OTT Hit Rate'!C12) | T12: =J12+M12+P12 | U12: =S12-T12 | W12: =V12-M12
C13: Lane Bryant | D13: =SUMIFS('Fab Plan-Final'!L:L,'Fab Plan-Final'!S:S,'Buyer Wise OTT Hit Rate'!$C$7,'Fab Plan-Final'!A:A,'Buyer Wise OTT Hit Rate'!C13) | E13: =SUMIFS('Fab Plan-Final'!M:M,'Fab Plan-Final'!S:S,'Buyer Wise OTT Hit Rate'!$C$7,'Fab Plan-Final'!A:A,'Buyer Wise OTT Hit Rate'!C13) | F13: =E13-D13 | G13: =IFERROR((E13/D13),"") | I13: =SUMIFS('Fab Plan-Final'!L:L, 'Fab Plan-Final'!S:S,"<"&$I$7, 'Fab Plan-Final'!A:A,'Buyer Wise OTT Hit Rate'!C13) | J13: =SUMIFS('Fab Plan-Final'!M:M, 'Fab Plan-Final'!S:S,"<"&$I$7, 'Fab Plan-Final'!A:A,'Buyer Wise OTT Hit Rate'!C13) | K13: =IFERROR(J13/I13,"") | L13: =J13-I13 | M13: =SUMIFS('Fab Plan-Final'!M:M, 'Fab Plan-Final'!S:S,">"&$M$7, 'Fab Plan-Final'!A:A,'Buyer Wise OTT Hit Rate'!C13) | N13: =IFERROR((J13+M13)/I13,"") | P13: =SUMIFS('Fab Plan-Final'!O:O, 'Fab Plan-Final'!S:S,"<"&$I$7, 'Fab Plan-Final'!A:A,'Buyer Wise OTT Hit Rate'!C13) | Q13: =(J13+P13)-I13 | S13: =SUMIFS('Fab Plan-Final'!L:L,'Fab Plan-Final'!A:A,'Buyer Wise OTT Hit Rate'!C13) | T13: =J13+M13+P13 | U13: =S13-T13 | V13: 240639.47 | W13: =V13-M13
C14: Sainsbury | D14: =SUMIFS('Fab Plan-Final'!L:L,'Fab Plan-Final'!S:S,'Buyer Wise OTT Hit Rate'!$C$7,'Fab Plan-Final'!A:A,'Buyer Wise OTT Hit Rate'!C14) | E14: =SUMIFS('Fab Plan-Final'!M:M,'Fab Plan-Final'!S:S,'Buyer Wise OTT Hit Rate'!$C$7,'Fab Plan-Final'!A:A,'Buyer Wise OTT Hit Rate'!C14) | F14: =E14-D14 | G14: =IFERROR((E14/D14),"") | I14: =SUMIFS('Fab Plan-Final'!L:L, 'Fab Plan-Final'!S:S,"<"&$I$7, 'Fab Plan-Final'!A:A,'Buyer Wise OTT Hit Rate'!C14) | J14: =SUMIFS('Fab Plan-Final'!M:M, 'Fab Plan-Final'!S:S,"<"&$I$7, 'Fab Plan-Final'!A:A,'Buyer Wise OTT Hit Rate'!C14) | K14: =IFERROR(J14/I14,"") | L14: =J14-I14 | M14: =SUMIFS('Fab Plan-Final'!M:M, 'Fab Plan-Final'!S:S,">"&$M$7, 'Fab Plan-Final'!A:A,'Buyer Wise OTT Hit Rate'!C14) | N14: =IFERROR((J14+M14)/I14,"") | P14: =SUMIFS('Fab Plan-Final'!O:O, 'Fab Plan-Final'!S:S,"<"&$I$7, 'Fab Plan-Final'!A:A,'Buyer Wise OTT Hit Rate'!C14) | Q14: =(J14+P14)-I14 | S14: =SUMIFS('Fab Plan-Final'!L:L,'Fab Plan-Final'!A:A,'Buyer Wise OTT Hit Rate'!C14) | T14: =J14+M14+P14 | U14: =S14-T14 | V14: 126361.9 | W14: =V14-M14
C15: YamamaY | D15: =SUMIFS('Fab Plan-Final'!L:L,'Fab Plan-Final'!S:S,'Buyer Wise OTT Hit Rate'!$C$7,'Fab Plan-Final'!A:A,'Buyer Wise OTT Hit Rate'!C15) | E15: =SUMIFS('Fab Plan-Final'!M:M,'Fab Plan-Final'!S:S,'Buyer Wise OTT Hit Rate'!$C$7,'Fab Plan-Final'!A:A,'Buyer Wise OTT Hit Rate'!C15) | F15: =E15-D15 | G15: =IFERROR((E15/D15),"") | I15: =SUMIFS('Fab Plan-Final'!L:L, 'Fab Plan-Final'!S:S,"<"&$I$7, 'Fab Plan-Final'!A:A,'Buyer Wise OTT Hit Rate'!C15) | J15: =SUMIFS('Fab Plan-Final'!M:M, 'Fab Plan-Final'!S:S,"<"&$I$7, 'Fab Plan-Final'!A:A,'Buyer Wise OTT Hit Rate'!C15) | K15: =IFERROR(J15/I15,"") | L15: =J15-I15 -> 0 | M15: =SUMIFS('Fab Plan-Final'!M:M, 'Fab Plan-Final'!S:S,">"&$M$7, 'Fab Plan-Final'!A:A,'Buyer Wise OTT Hit Rate'!C15) | N15: =IFERROR((J15+M15)/I15,"") | P15: =SUMIFS('Fab Plan-Final'!O:O, 'Fab Plan-Final'!S:S,"<"&$I$7, 'Fab Plan-Final'!A:A,'Buyer Wise OTT Hit Rate'!C15) | Q15: =(J15+P15)-I15 | S15: =SUMIFS('Fab Plan-Final'!L:L,'Fab Plan-Final'!A:A,'Buyer Wise OTT Hit Rate'!C15) | T15: =J15+M15+P15 | U15: =S15-T15 | W15: =V15-M15
C16: M & S - T61 (KPK) | D16: =SUMIFS('Fab Plan-Final'!L:L,'Fab Plan-Final'!S:S,'Buyer Wise OTT Hit Rate'!$C$7,'Fab Plan-Final'!A:A,'Buyer Wise OTT Hit Rate'!C16) | E16: =SUMIFS('Fab Plan-Final'!M:M,'Fab Plan-Final'!S:S,'Buyer Wise OTT Hit Rate'!$C$7,'Fab Plan-Final'!A:A,'Buyer Wise OTT Hit Rate'!C16) | F16: =E16-D16 | G16: =IFERROR((E16/D16),"") | I16: =SUMIFS('Fab Plan-Final'!L:L, 'Fab Plan-Final'!S:S,"<"&$I$7, 'Fab Plan-Final'!A:A,'Buyer Wise OTT Hit Rate'!C16) | J16: =SUMIFS('Fab Plan-Final'!M:M, 'Fab Plan-Final'!S:S,"<"&$I$7, 'Fab Plan-Final'!A:A,'Buyer Wise OTT Hit Rate'!C16) | K16: =IFERROR(J16/I16,"") | L16: =J16-I16 | M16: =SUMIFS('Fab Plan-Final'!M:M, 'Fab Plan-Final'!S:S,">"&$M$7, 'Fab Plan-Final'!A:A,'Buyer Wise OTT Hit Rate'!C16) | N16: =IFERROR((J16+M16)/I16,"") | P16: =SUMIFS('Fab Plan-Final'!O:O, 'Fab Plan-Final'!S:S,"<"&$I$7, 'Fab Plan-Final'!A:A,'Buyer Wise OTT Hit Rate'!C16) | Q16: =(J16+P16)-I16 | S16: =SUMIFS('Fab Plan-Final'!L:L,'Fab Plan-Final'!A:A,'Buyer Wise OTT Hit Rate'!C16) | T16: =J16+M16+P16 | U16: =S16-T16 | V16: 873.423 | W16: =V16-M16
C17: LIDL | D17: =SUMIFS('Fab Plan-Final'!L:L,'Fab Plan-Final'!S:S,'Buyer Wise OTT Hit Rate'!$C$7,'Fab Plan-Final'!A:A,'Buyer Wise OTT Hit Rate'!C17) | E17: =SUMIFS('Fab Plan-Final'!M:M,'Fab Plan-Final'!S:S,'Buyer Wise OTT Hit Rate'!$C$7,'Fab Plan-Final'!A:A,'Buyer Wise OTT Hit Rate'!C17) | F17: =E17-D17 | G17: =IFERROR((E17/D17),"") | I17: =SUMIFS('Fab Plan-Final'!L:L, 'Fab Plan-Final'!S:S,"<"&$I$7, 'Fab Plan-Final'!A:A,'Buyer Wise OTT Hit Rate'!C17) | J17: =SUMIFS('Fab Plan-Final'!M:M, 'Fab Plan-Final'!S:S,"<"&$I$7, 'Fab Plan-Final'!A:A,'Buyer Wise OTT Hit Rate'!C17) | K17: =IFERROR(J17/I17,"") | L17: =J17-I17 | M17: =SUMIFS('Fab Plan-Final'!M:M, 'Fab Plan-Final'!S:S,">"&$M$7, 'Fab Plan-Final'!A:A,'Buyer Wise OTT Hit Rate'!C17) | N17: =IFERROR((J17+M17)/I17,"") | P17: =SUMIFS('Fab Plan-Final'!O:O, 'Fab Plan-Final'!S:S,"<"&$I$7, 'Fab Plan-Final'!A:A,'Buyer Wise OTT Hit Rate'!C17) | Q17: =(J17+P17)-I17 | S17: =SUMIFS('Fab Plan-Final'!L:L,'Fab Plan-Final'!A:A,'Buyer Wise OTT Hit Rate'!C17) | T17: =J17+M17+P17 | U17: =S17-T17 | V17: 331.8 | W17: =V17-M17
C18: H & M | D18: =SUMIFS('Fab Plan-Final'!L:L,'Fab Plan-Final'!S:S,'Buyer Wise OTT Hit Rate'!$C$7,'Fab Plan-Final'!A:A,'Buyer Wise OTT Hit Rate'!C18) | E18: =SUMIFS('Fab Plan-Final'!M:M,'Fab Plan-Final'!S:S,'Buyer Wise OTT Hit Rate'!$C$7,'Fab Plan-Final'!A:A,'Buyer Wise OTT Hit Rate'!C18) | F18: =E18-D18 | G18: =IFERROR((E18/D18),"") | I18: =SUMIFS('Fab Plan-Final'!L:L, 'Fab Plan-Final'!S:S,"<"&$I$7, 'Fab Plan-Final'!A:A,'Buyer Wise OTT Hit Rate'!C18) | J18: =SUMIFS('Fab Plan-Final'!M:M, 'Fab Plan-Final'!S:S,"<"&$I$7, 'Fab Plan-Final'!A:A,'Buyer Wise OTT Hit Rate'!C18) | K18: =IFERROR(J18/I18,"") | L18: =J18-I18 -> 0 | M18: =SUMIFS('Fab Plan-Final'!M:M, 'Fab Plan-Final'!S:S,">"&$M$7, 'Fab Plan-Final'!A:A,'Buyer Wise OTT Hit Rate'!C18) | N18: =IFERROR((J18+M18)/I18,"") | P18: =SUMIFS('Fab Plan-Final'!O:O, 'Fab Plan-Final'!S:S,"<"&$I$7, 'Fab Plan-Final'!A:A,'Buyer Wise OTT Hit Rate'!C18) | Q18: =(J18+P18)-I18 | S18: =SUMIFS('Fab Plan-Final'!L:L,'Fab Plan-Final'!A:A,'Buyer Wise OTT Hit Rate'!C18) | T18: =J18+M18+P18 | U18: =S18-T18 | V18: 47 | W18: =V18-M18
C19: M & S - T71 | D19: =SUMIFS('Fab Plan-Final'!L:L,'Fab Plan-Final'!S:S,'Buyer Wise OTT Hit Rate'!$C$7,'Fab Plan-Final'!A:A,'Buyer Wise OTT Hit Rate'!C19) | E19: =SUMIFS('Fab Plan-Final'!M:M,'Fab Plan-Final'!S:S,'Buyer Wise OTT Hit Rate'!$C$7,'Fab Plan-Final'!A:A,'Buyer Wise OTT Hit Rate'!C19) | F19: =E19-D19 | G19: =IFERROR((E19/D19),"") | I19: =SUMIFS('Fab Plan-Final'!L:L, 'Fab Plan-Final'!S:S,"<"&$I$7, 'Fab Plan-Final'!A:A,'Buyer Wise OTT Hit Rate'!C19) | J19: =SUMIFS('Fab Plan-Final'!M:M, 'Fab Plan-Final'!S:S,"<"&$I$7, 'Fab Plan-Final'!A:A,'Buyer Wise OTT Hit Rate'!C19) | K19: =IFERROR(J19/I19,"") | L19: =J19-I19 | M19: =SUMIFS('Fab Plan-Final'!M:M, 'Fab Plan-Final'!S:S,">"&$M$7, 'Fab Plan-Final'!A:A,'Buyer Wise OTT Hit Rate'!C19) | N19: =IFERROR((J19+M19)/I19,"") | P19: =SUMIFS('Fab Plan-Final'!O:O, 'Fab Plan-Final'!S:S,"<"&$I$7, 'Fab Plan-Final'!A:A,'Buyer Wise OTT Hit Rate'!C19) | Q19: =(J19+P19)-I19 | S19: =SUMIFS('Fab Plan-Final'!L:L,'Fab Plan-Final'!A:A,'Buyer Wise OTT Hit Rate'!C19) | T19: =J19+M19+P19 | U19: =S19-T19 | V19: 2097.5538 | W19: =V19-M19
C20: M & S - T61 (SHK) | D20: =SUMIFS('Fab Plan-Final'!L:L,'Fab Plan-Final'!S:S,'Buyer Wise OTT Hit Rate'!$C$7,'Fab Plan-Final'!A:A,'Buyer Wise OTT Hit Rate'!C20) | E20: =SUMIFS('Fab Plan-Final'!M:M,'Fab Plan-Final'!S:S,'Buyer Wise OTT Hit Rate'!$C$7,'Fab Plan-Final'!A:A,'Buyer Wise OTT Hit Rate'!C20) | F20: =E20-D20 | G20: =IFERROR((E20/D20),"") | I20: =SUMIFS('Fab Plan-Final'!L:L, 'Fab Plan-Final'!S:S,"<"&$I$7, 'Fab Plan-Final'!A:A,'Buyer Wise OTT Hit Rate'!C20) | J20: =SUMIFS('Fab Plan-Final'!M:M, 'Fab Plan-Final'!S:S,"<"&$I$7, 'Fab Plan-Final'!A:A,'Buyer Wise OTT Hit Rate'!C20) | K20: =IFERROR(J20/I20,"") | L20: =J20-I20 | M20: =SUMIFS('Fab Plan-Final'!M:M, 'Fab Plan-Final'!S:S,">"&$M$7, 'Fab Plan-Final'!A:A,'Buyer Wise OTT Hit Rate'!C20) | N20: =IFERROR((J20+M20)/I20,"") | P20: =SUMIFS('Fab Plan-Final'!O:O, 'Fab Plan-Final'!S:S,"<"&$I$7, 'Fab Plan-Final'!A:A,'Buyer Wise OTT Hit Rate'!C20) | Q20: =(J20+P20)-I20 | S20: =SUMIFS('Fab Plan-Final'!L:L,'Fab Plan-Final'!A:A,'Buyer Wise OTT Hit Rate'!C20) | T20: =J20+M20+P20 | U20: =S20-T20 | V20: 3396.781 | W20: =V20-M20
C21: M & S - T51 | D21: =SUMIFS('Fab Plan-Final'!L:L,'Fab Plan-Final'!S:S,'Buyer Wise OTT Hit Rate'!$C$7,'Fab Plan-Final'!A:A,'Buyer Wise OTT Hit Rate'!C21) | E21: =SUMIFS('Fab Plan-Final'!M:M,'Fab Plan-Final'!S:S,'Buyer Wise OTT Hit Rate'!$C$7,'Fab Plan-Final'!A:A,'Buyer Wise OTT Hit Rate'!C21) | F21: =E21-D21 | G21: =IFERROR((E21/D21),"") | I21: =SUMIFS('Fab Plan-Final'!L:L, 'Fab Plan-Final'!S:S,"<"&$I$7, 'Fab Plan-Final'!A:A,'Buyer Wise OTT Hit Rate'!C21) | J21: =SUMIFS('Fab Plan-Final'!M:M, 'Fab Plan-Final'!S:S,"<"&$I$7, 'Fab Plan-Final'!A:A,'Buyer Wise OTT Hit Rate'!C21) | K21: =IFERROR(J21/I21,"") | L21: =J21-I21 -> 0 | M21: =SUMIFS('Fab Plan-Final'!M:M, 'Fab Plan-Final'!S:S,">"&$M$7, 'Fab Plan-Final'!A:A,'Buyer Wise OTT Hit Rate'!C21) | N21: =IFERROR((J21+M21)/I21,"") | P21: =SUMIFS('Fab Plan-Final'!O:O, 'Fab Plan-Final'!S:S,"<"&$I$7, 'Fab Plan-Final'!A:A,'Buyer Wise OTT Hit Rate'!C21) | Q21: =(J21+P21)-I21 | S21: =SUMIFS('Fab Plan-Final'!L:L,'Fab Plan-Final'!A:A,'Buyer Wise OTT Hit Rate'!C21) | T21: =J21+M21+P21 | U21: =S21-T21
C22: Primark Limited | D22: =SUMIFS('Fab Plan-Final'!L:L,'Fab Plan-Final'!S:S,'Buyer Wise OTT Hit Rate'!$C$7,'Fab Plan-Final'!A:A,'Buyer Wise OTT Hit Rate'!C22) | E22: =SUMIFS('Fab Plan-Final'!M:M,'Fab Plan-Final'!S:S,'Buyer Wise OTT Hit Rate'!$C$7,'Fab Plan-Final'!A:A,'Buyer Wise OTT Hit Rate'!C22) | F22: =E22-D22 | G22: =IFERROR((E22/D22),"") | I22: =SUMIFS('Fab Plan-Final'!L:L, 'Fab Plan-Final'!S:S,"<"&$I$7, 'Fab Plan-Final'!A:A,'Buyer Wise OTT Hit Rate'!C22) | J22: =SUMIFS('Fab Plan-Final'!M:M, 'Fab Plan-Final'!S:S,"<"&$I$7, 'Fab Plan-Final'!A:A,'Buyer Wise OTT Hit Rate'!C22) | K22: =IFERROR(J22/I22,"") | L22: =J22-I22 | M22: =SUMIFS('Fab Plan-Final'!M:M, 'Fab Plan-Final'!S:S,">"&$M$7, 'Fab Plan-Final'!A:A,'Buyer Wise OTT Hit Rate'!C22) | N22: =IFERROR((J22+M22)/I22,"") | P22: =SUMIFS('Fab Plan-Final'!O:O, 'Fab Plan-Final'!S:S,"<"&$I$7, 'Fab Plan-Final'!A:A,'Buyer Wise OTT Hit Rate'!C22) | Q22: =(J22+P22)-I22 | S22: =SUMIFS('Fab Plan-Final'!L:L,'Fab Plan-Final'!A:A,'Buyer Wise OTT Hit Rate'!C22) | T22: =J22+M22+P22 | U22: =S22-T22
C23: M&S T14 | D23: =SUMIFS('Fab Plan-Final'!L:L,'Fab Plan-Final'!S:S,'Buyer Wise OTT Hit Rate'!$C$7,'Fab Plan-Final'!A:A,'Buyer Wise OTT Hit Rate'!C23) | E23: =SUMIFS('Fab Plan-Final'!M:M,'Fab Plan-Final'!S:S,'Buyer Wise OTT Hit Rate'!$C$7,'Fab Plan-Final'!A:A,'Buyer Wise OTT Hit Rate'!C23) | F23: =E23-D23 | G23: =IFERROR((E23/D23),"") | I23: =SUMIFS('Fab Plan-Final'!L:L, 'Fab Plan-Final'!S:S,"<"&$I$7, 'Fab Plan-Final'!A:A,'Buyer Wise OTT Hit Rate'!C23) | J23: =SUMIFS('Fab Plan-Final'!M:M, 'Fab Plan-Final'!S:S,"<"&$I$7, 'Fab Plan-Final'!A:A,'Buyer Wise OTT Hit Rate'!C23) | K23: =IFERROR(J23/I23,"") | L23: =J23-I23 | M23: =SUMIFS('Fab Plan-Final'!M:M, 'Fab Plan-Final'!S:S,">"&$M$7, 'Fab Plan-Final'!A:A,'Buyer Wise OTT Hit Rate'!C23) | N23: =IFERROR((J23+M23)/I23,"") | P23: =SUMIFS('Fab Plan-Final'!O:O, 'Fab Plan-Final'!S:S,"<"&$I$7, 'Fab Plan-Final'!A:A,'Buyer Wise OTT Hit Rate'!C23) | Q23: =(J23+P23)-I23 | S23: =SUMIFS('Fab Plan-Final'!L:L,'Fab Plan-Final'!A:A,'Buyer Wise OTT Hit Rate'!C23) | T23: =J23+M23+P23 | U23: =S23-T23
C24: Grand Total | D24: =SUM(D10:D23) | E24: =SUM(E10:E23) | F24: =SUM(F10:F23) | G24: =IFERROR(E24/D24,"") | I24: =SUM(I10:I23) | J24: =SUM(J10:J23) | K24: =IFERROR(J24/I24,"") | L24: =SUM(L10:L23) | M24: =SUM(M10:M23) | N24: =IFERROR((J24+M24)/I24,"") | P24: =SUM(P10:P23) | Q24: =SUM(Q10:Q23) | S24: =SUM(S10:S23) | T24: =SUM(T10:T23) | U24: =SUM(U10:U23)

Sheet Fab Plan-Final
J1: =L1/3 | K1: =SUBTOTAL(9,K3:K99956) | L1: =SUBTOTAL(9,L3:L998684) | M1: =SUBTOTAL(9,M3:M998684) | N1: =SUBTOTAL(9,N3:N998684) | O1: =SUBTOTAL(9,O3:O998684) | P1: =SUBTOTAL(9,P3:P998684) | AM1: qqTRIM(AJ3)&TRIM(AL3)&TRIM(AK3) | AN1: QQSUMIFS('[DOC -280+217.xlsx]217'!$AQ:$AQ,'[DOC -280+217.xlsx]217'!$AP:$AP,AM3) | AO1: QQIF(AN3=0,"#NA",SUMIFS('[DOC -280+217.xlsx]217'!$AR:$AR,'[DOC -280+217.xlsx]217'!$AP:$AP,AM3)) | AP1: qqSUMIFS(M:M,AM:AM,AM3)+SUMIFS(O:O,AM:AM,AM3) | AQ1: qqSUMIFS(L:L,AM:AM,AM3) | AR1: qqAQ3-AP3 | AS1: qqIF(AN3>=AQ3,"ok","ck") | AT1: qq-p3 | AU1: qqIF(SUMIFS(AT:AT,AM:AM,AM3)>AO3,(SUMIFS(AT:AT,AM:AM,AM3)-AO3)) | AV1: qqVLOOKUP(AM3,'[DOC -280+217.xlsx]217'!$AP:$AQ,2,FALSE) | AW1: qqINDEX('[DOC -280+217.xlsx]217'!$AF:$AF,MATCH(AM3,'[DOC -280+217.xlsx]217'!$AP:$AP,0)) | AX1: qqAN3-AP3
A2: Buyer | B2: Main OC | C2: line plan oc match | D2: Season | E2: Fabric Req Date | F2: Style Name | G2: Psbl RFD | H2: Hues Code | I2: Article Name | J2: Color | K2: Req Qty Kg | L2: Req Qty(Mtr) | M2: RFD Qty. | N2: Balance to RFD | O2: Recovered Qty | P2: Final Balance | Q2: PO/PRPO No(Supplier Name) | R2: Category | S2: Agreed RFD Date-Hues | T2: Agreed RFD Date. | U2: Hues Proposed RFD Date/Flow | V2: Hues Feedback | W2: Plan Remarks | X2: Plan Month | Y2: Scm Req date | Z2: Dye Batch | AA2: Dye Date | AB2: Finish Date | AC2: Rfd Date | AD2: Dye Plan Date | AE2: Finish Plan Date | AF2: Rfd Plan date | AG2: Remarks | AH2: Hues Proposed RFD Date/Flow | AI2: Plan Remarks | AJ2: Huees Po | AK2: Hues Color | AL2: Hues Fabric | AM2: And | AN2: Tps Rfd Qty | AO2: Taps Balance | AP2: Ott Rdf Qty | AQ2: Ott Req | AR2: Ott Blnc | AS2: Recheck | AT2: Final Balance OTT | AU2: Psbl to rfd | AV2: Po Findable Test/RFD QTY | AW2: Po compleate % | AX2: Psbl to rfd another view
A3: M & S - T61 (KPK) | G3: =AU3 | I3: SJ 100% BCI Combed Compact Cotton 120gsm CW62” | J3: 64270 PINK | K3: =P3/3 | L3: 0 | M3: =L3 | N3: =M3-L3 | P3: =N3+O3 | Q3: 427783 | R3: Solid | S3: 46321 | U3: 46321 | Y3: 46320 | AJ3: 427783 | AK3: 64270 Pink | AL3: 120 | AM3: =TRIM(AJ3)&TRIM(AL3)&TRIM(AK3) | AN3: 189 | AO3: -9 | AP3: =SUMIFS(M:M,AM:AM,AM3)+SUMIFS(O:O,AM:AM,AM3) | AQ3: =SUMIFS(L:L,AM:AM,AM3) | AR3: =AQ3-AP3 | AS3: =IF(AN3>=AQ3,"ok","ck") | AT3: =-P3 | AU3: =IF(SUMIFS(AT:AT,AM:AM,AM3)>AO3,(SUMIFS(AT:AT,AM:AM,AM3)-AO3)) | AV3: 189 | AW3: 1.05 | AX3: =AN3-AP3
A4: M & S - T61 (KPK) | G4: =AU4 | I4: SJ 95% BCI Cmd Cmpt CTN 5% Inv Ly 140gsm CW61” | J4: 64270 PINK | K4: =P4/3 | L4: 21.92 | N4: =M4-L4 | P4: =N4+O4 | Q4: 427783 | R4: Solid | S4: 46320 | U4: 46320 | Y4: 46320 | AJ4: 427783 | AK4: 64270 Pink | AL4: 140 | AM4: =TRIM(AJ4)&TRIM(AL4)&TRIM(AK4) | AN4: 1543 | AO4: 22 | AP4: =SUMIFS(M:M,AM:AM,AM4)+SUMIFS(O:O,AM:AM,AM4) | AQ4: =SUMIFS(L:L,AM:AM,AM4) | AR4: =AQ4-AP4 | AS4: =IF(AN4>=AQ4,"ok","ck") | AT4: =-P4 | AU4: =IF(SUMIFS(AT:AT,AM:AM,AM4)>AO4,(SUMIFS(AT:AT,AM:AM,AM4)-AO4)) | AV4: 1543 | AW4: 0.986 | AX4: =AN4-AP4
A5: M & S - T61 (KPK) | G5: =AU5 | I5: SJ 95% BCI Cmd Cmpt CTN 5% Inv Ly 140gsm CW61” | J5: Ivory 80762 | K5: =P5/3 | L5: 0 | M5: =L5 | N5: =M5-L5 | P5: =N5+O5 | Q5: 457136 | R5: Solid | S5: 46320 | U5: 46320 | Y5: 46320 | AJ5: 457136 | AK5: IVORY 80762 | AL5: 140 | AM5: =TRIM(AJ5)&TRIM(AL5)&TRIM(AK5) | AN5: 600 | AO5: -16.3 | AP5: =SUMIFS(M:M,AM:AM,AM5)+SUMIFS(O:O,AM:AM,AM5) | AQ5: =SUMIFS(L:L,AM:AM,AM5) | AR5: =AQ5-AP5 | AS5: =IF(AN5>=AQ5,"ok","ck") | AT5: =-P5 | AU5: =IF(SUMIFS(AT:AT,AM:AM,AM5)>AO5,(SUMIFS(AT:AT,AM:AM,AM5)-AO5)) | AV5: 600 | AW5: 1.028 | AX5: =AN5-AP5
A6: LIDL | G6: =AU6 | I6: 48% LYOCELL 47% CMIA COTTON 5% ELASTANE RIB 2X2 GSM-190 CW-111 CM/44 INCH | J6: Tornado | K6: =P6/3 | L6: 0 | N6: =M6-L6 | P6: =N6+O6 | Q6: 438197 | R6: Solid | S6: 46328 | U6: 46328 | Y6: 46328 | AJ6: 438197#Style-2604 (MENS)-Creora | AK6: 18-3907 TCX(Tornado) | AL6: 190 | AM6: =TRIM(AJ6)&TRIM(AL6)&TRIM(AK6) | AN6: 69621.11 | AO6: 9428.16 | AP6: =SUMIFS(M:M,AM:AM,AM6)+SUMIFS(O:O,AM:AM,AM6) | AQ6: =SUMIFS(L:L,AM:AM,AM6) | AR6: =AQ6-AP6 | AS6: =IF(AN6>=AQ6,"ok","ck") | AT6: =-P6 | AU6: =IF(SUMIFS(AT:AT,AM:AM,AM6)>AO6,(SUMIFS(AT:AT,AM:AM,AM6)-AO6)) | AV6: 43 | AW6: 0.159 | AX6: =AN6-AP6
A7: LIDL | G7: =AU7 | I7: 48% LYOCELL 47% CMIA COTTON 5% ELASTANE RIB 2X2 GSM-190 CW-111 CM/44 INCH | J7: Tornado | K7: =P7/3 | L7: 0 | N7: =M7-L7 | P7: =N7+O7 | Q7: 438197 | R7: Solid | S7: 46331 | U7: 46331 | Y7: 46331 | AJ7: 438197#Style-2604 (MENS)-Creora | AK7: 18-3907 TCX(Tornado) | AL7: 190 | AM7: =TRIM(AJ7)&TRIM(AL7)&TRIM(AK7) | AN7: 69621.11 | AO7: 9428.16 | AP7: =SUMIFS(M:M,AM:AM,AM7)+SUMIFS(O:O,AM:AM,AM7) | AQ7: =SUMIFS(L:L,AM:AM,AM7) | AR7: =AQ7-AP7 | AS7: =IF(AN7>=AQ7,"ok","ck") | AT7: =-P7 | AU7: =IF(SUMIFS(AT:AT,AM:AM,AM7)>AO7,(SUMIFS(AT:AT,AM:AM,AM7)-AO7)) | AV7: 43 | AW7: 0.159 | AX7: =AN7-AP7
A8: M & S - T61 (KPK) | G8: =AU8 | I8: SJ 95% BCI Cmd Cmpt CTN 5% Inv Ly 140gsm CW61” | J8: 62551 PINK | K8: =P8/3 | L8: -11.647 | M8: =L8 | N8: =M8-L8 | P8: =N8+O8 | Q8: 440575 | R8: Solid | S8: 46320 | U8: 46320 | Y8: 46320 | AJ8: 440575 | AK8: 62551 Pink | AL8: 140 | AM8: =TRIM(AJ8)&TRIM(AL8)&TRIM(AK8) | AN8: 3981 | AO8: -85.47 | AP8: =SUMIFS(M:M,AM:AM,AM8)+SUMIFS(O:O,AM:AM,AM8) | AQ8: =SUMIFS(L:L,AM:AM,AM8) | AR8: =AQ8-AP8 | AS8: =IF(AN8>=AQ8,"ok","ck") | AT8: =-P8 | AU8: =IF(SUMIFS(AT:AT,AM:AM,AM8)>AO8,(SUMIFS(AT:AT,AM:AM,AM8)-AO8)) | AV8: 3981 | AW8: 1.022 | AX8: =AN8-AP8
A9: M & S - T61 (KPK) | G9: =AU9 | I9: SJ 95% BCI Cmd Cmpt CTN 5% Inv Ly 140gsm CW63” | J9: ROSE QUARTZ 23830 | K9: =P9/3 | L9: 2894 | N9: =M9-L9 | P9: =N9+O9 | Q9: 468883 | R9: Solid | S9: 46344 | U9: 18th Nov-2,894 mtr, 21st Nov-1,106 mtr, 22nd Nov-2,728 mtr, Rest Qty-23rd Nov | Y9: 46342 | AJ9: 468883 | AK9: ROSE QUARTS 23830 | AL9: 140 | AM9: =TRIM(AJ9)&TRIM(AL9)&TRIM(AK9) | AN9: 0 | AO9: #NA | AP9: =SUMIFS(M:M,AM:AM,AM9)+SUMIFS(O:O,AM:AM,AM9) | AQ9: =SUMIFS(L:L,AM:AM,AM9) | AR9: =AQ9-AP9 | AS9: =IF(AN9>=AQ9,"ok","ck") | AT9: =-P9 | AU9: =IF(SUMIFS(AT:AT,AM:AM,AM9)>AO9,(SUMIFS(AT:AT,AM:AM,AM9)-AO9)) | AV9: 0 | AW9: 0 | AX9: =AN9-AP9
A10: M & S - T61 (KPK) | G10: =AU10 | I10: SJ 95% BCI Cmd Cmpt CTN 5% Inv Ly 140gsm CW63” | J10: ROSE QUARTZ 23830 | K10: =P10/3 | L10: 1106 | N10: =M10-L10 | P10: =N10+O10 | Q10: 468883 | R10: Solid | S10: 46347 | U10: 18th Nov-2,894 mtr, 21st Nov-1,106 mtr, 22nd Nov-2,728 mtr, Rest Qty-23rd Nov | Y10: 46342 | AJ10: 468883 | AK10: ROSE QUARTS 23830 | AL10: 140 | AM10: =TRIM(AJ10)&TRIM(AL10)&TRIM(AK10) | AN10: 0 | AO10: #NA | AP10: =SUMIFS(M:M,AM:AM,AM10)+SUMIFS(O:O,AM:AM,AM10) | AQ10: =SUMIFS(L:L,AM:AM,AM10) | AR10: =AQ10-AP10 | AS10: =IF(AN10>=AQ10,"ok","ck") | AT10: =-P10 | AU10: =IF(SUMIFS(AT:AT,AM:AM,AM10)>AO10,(SUMIFS(AT:AT,AM:AM,AM10)-AO10)) | AV10: 0 | AW10: 0 | AX10: =AN10-AP10
A11: M & S - T61 (KPK) | G11: =AU11 | I11: SJ 100% BCI Combed Compact Cotton 120gsm CW62” | J11: ROSE QUARTS 23830 | K11: =P11/3 | L11: 0.404 | N11: =M11-L11 | P11: =N11+O11 | Q11: 468884 | R11: Solid | S11: 46338 | U11: 46338 | Y11: 46338 | AJ11: 468884 | AK11: ROSE QUARTS 23830 | AL11: 120 | AM11: =TRIM(AJ11)&TRIM(AL11)&TRIM(AK11) | AN11: 0 | AO11: #NA | AP11: =SUMIFS(M:M,AM:AM,AM11)+SUMIFS(O:O,AM:AM,AM11) | AQ11: =SUMIFS(L:L,AM:AM,AM11) | AR11: =AQ11-AP11 | AS11: =IF(AN11>=AQ11,"ok","ck") | AT11: =-P11 | AU11: =IF(SUMIFS(AT:AT,AM:AM,AM11)>AO11,(SUMIFS(AT:AT,AM:AM,AM11)-AO11)) | AV11: 0 | AW11: 0 | AX11: =AN11-AP11
A12: M & S - T61 (KPK) | G12: =AU12 | I12: SJ 100% BCI Combed Compact Cotton 120gsm CW62” | J12: ROSE QUARTS 23830 | K12: =P12/3 | L12: 0.404 | N12: =M12-L12 | P12: =N12+O12 | Q12: 468884 | R12: Solid | S12: 46338 | U12: 46338 | Y12: 46338 | AJ12: 468884 | AK12: ROSE QUARTS 23830 | AL12: 120 | AM12: =TRIM(AJ12)&TRIM(AL12)&TRIM(AK12) | AN12: 0 | AO12: #NA | AP12: =SUMIFS(M:M,AM:AM,AM12)+SUMIFS(O:O,AM:AM,AM12) | AQ12: =SUMIFS(L:L,AM:AM,AM12) | AR12: =AQ12-AP12 | AS12: =IF(AN12>=AQ12,"ok","ck") | AT12: =-P12 | AU12: =IF(SUMIFS(AT:AT,AM:AM,AM12)>AO12,(SUMIFS(AT:AT,AM:AM,AM12)-AO12)) | AV12: 0 | AW12: 0 | AX12: =AN12-AP12
A13: T61-KPK | G13: =AU13 | I13: SJ 95% BCI Cmd Cmpt CTN 5% Inv Ly 140gsm CW61” | J13: White 10001 | K13: =P13/3 | L13: 1024.501 | M13: 1024.501 | N13: =M13-L13 | P13: =N13+O13 | R13: Solid | S13: 46327 | U13: 1st Nov-10th Nov-1.5k mtr/day, 11th Nov-25th Nov- 2.5k mtr, FOC will deliver on 26th Nov | Y13: 46320 | AL13: 140 | AM13: =TRIM(AJ13)&TRIM(AL13)&TRIM(AK13) | AN13: 0 | AO13: #NA | AP13: =SUMIFS(M:M,AM:AM,AM13)+SUMIFS(O:O,AM:AM,AM13) | AQ13: =SUMIFS(L:L,AM:AM,AM13) | AR13: =AQ13-AP13 | AS13: =IF(AN13>=AQ13,"ok","ck") | AT13: =-P13 | AU13: =IF(SUMIFS(AT:AT,AM:AM,AM13)>AO13,(SUMIFS(AT:AT,AM:AM,AM13)-AO13)) | AV13: #N/A | AW13: #N/A | AX13: =AN13-AP13
A14: Sainsbury | G14: =AU14 | I14: S/J- Solid 95%Cot 5%Inv Lycra 140gsm with PCF 66 | J14: Black | K14: =P14/3 | L14: 480 | N14: =M14-L14 | P14: =N14+O14 | Q14: 446252 | R14: Solid | S14: 46325 | U14: 46325 | Y14: 46320 | AJ14: 446252 | AK14: Black | AL14: 140 | AM14: =TRIM(AJ14)&TRIM(AL14)&TRIM(AK14) | AN14: 16424.84 | AO14: 2141.13 | AP14: =SUMIFS(M:M,AM:AM,AM14)+SUMIFS(O:O,AM:AM,AM14) | AQ14: =SUMIFS(L:L,AM:AM,AM14) | AR14: =AQ14-AP14 | AS14: =IF(AN14>=AQ14,"ok","ck") | AT14: =-P14 | AU14: =IF(SUMIFS(AT:AT,AM:AM,AM14)>AO14,(SUMIFS(AT:AT,AM:AM,AM14)-AO14)) | AV14: 317 | AW14: 0.744 | AX14: =AN14-AP14
A15: Sainsbury | G15: =AU15 | I15: S/J- Solid 95%Cot 5%Inv Lycra 140gsm with PCF 66 | J15: Black | K15: =P15/3 | L15: 800.789 | N15: =M15-L15 | P15: =N15+O15 | Q15: 446252 | R15: Solid | S15: 46325 | U15: 46325 | Y15: 46321 | AJ15: 446252 | AK15: Black | AL15: 140 | AM15: =TRIM(AJ15)&TRIM(AL15)&TRIM(AK15) | AN15: 16424.84 | AO15: 2141.13 | AP15: =SUMIFS(M:M,AM:AM,AM15)+SUMIFS(O:O,AM:AM,AM15) | AQ15: =SUMIFS(L:L,AM:AM,AM15) | AR15: =AQ15-AP15 | AS15: =IF(AN15>=AQ15,"ok","ck") | AT15: =-P15 | AU15: =IF(SUMIFS(AT:AT,AM:AM,AM15)>AO15,(SUMIFS(AT:AT,AM:AM,AM15)-AO15)) | AV15: 317 | AW15: 0.744 | AX15: =AN15-AP15
A16: LIDL | G16: =AU16 | I16: KNIT SINGLE JERSEY CMIA COTTON 95% ELASTANE CRERORA 5% GSM-160 CW-167.6 CM/66 INCH | J16: MID GREY MELANGE | K16: =P16/3 | L16: 0 | M16: =L16 | N16: =M16-L16 | P16: =N16+O16 | Q16: 457575 | R16: Solid | S16: 46320 | U16: 46320 | Y16: 46320 | AJ16: 457575#Style-2604(Menswear/ Boxer)-Creora | AK16: Mid Grey Melange | AL16: 160 | AM16: =TRIM(AJ16)&TRIM(AL16)&TRIM(AK16) | AN16: 2795 | AO16: -56 | AP16: =SUMIFS(M:M,AM:AM,AM16)+SUMIFS(O:O,AM:AM,AM16) | AQ16: =SUMIFS(L:L,AM:AM,AM16) | AR16: =AQ16-AP16 | AS16: =IF(AN16>=AQ16,"ok","ck") | AT16: =-P16 | AU16: =IF(SUMIFS(AT:AT,AM:AM,AM16)>AO16,(SUMIFS(AT:AT,AM:AM,AM16)-AO16)) | AV16: 2795 | AW16: 1.02 | AX16: =AN16-AP16
A17: LIDL | G17: =AU17 | I17: KNIT SINGLE JERSEY CMIA COTTON 95% ELASTANE CRERORA 5% GSM-160 CW-167.6 CM/66 INCH | J17: MID GREY MELANGE | K17: =P17/3 | L17: 0 | M17: =L17 | N17: =M17-L17 | P17: =N17+O17 | Q17: 457575 | R17: Solid | S17: 46324 | U17: 46324 | Y17: 46324 | AJ17: 457575#Style-2604(Menswear/ Boxer)-Creora | AK17: Mid Grey Melange | AL17: 160 | AM17: =TRIM(AJ17)&TRIM(AL17)&TRIM(AK17) | AN17: 2795 | AO17: -56 | AP17: =SUMIFS(M:M,AM:AM,AM17)+SUMIFS(O:O,AM:AM,AM17) | AQ17: =SUMIFS(L:L,AM:AM,AM17) | AR17: =AQ17-AP17 | AS17: =IF(AN17>=AQ17,"ok","ck") | AT17: =-P17 | AU17: =IF(SUMIFS(AT:AT,AM:AM,AM17)>AO17,(SUMIFS(AT:AT,AM:AM,AM17)-AO17)) | AV17: 2795 | AW17: 1.02 | AX17: =AN17-AP17
A18: Sainsbury | G18: =AU18 | I18: S/J Gusset 100% Cotton 110gsm CW64 | J18: TU BLACK | K18: =P18/3 | L18: -0.001 | M18: =L18 | N18: =M18-L18 | P18: =N18+O18 | Q18: 454634 | R18: Solid | S18: 46342 | U18: 46342 | Y18: 46342 | AJ18: 454634 | AK18: Tu Black | AL18: 110 | AM18: =TRIM(AJ18)&TRIM(AL18)&TRIM(AK18) | AN18: 96 | AO18: -2.02 | AP18: =SUMIFS(M:M,AM:AM,AM18)+SUMIFS(O:O,AM:AM,AM18) | AQ18: =SUMIFS(L:L,AM:AM,AM18) | AR18: =AQ18-AP18 | AS18: =IF(AN18>=AQ18,"ok","ck") | AT18: =-P18 | AU18: =IF(SUMIFS(AT:AT,AM:AM,AM18)>AO18,(SUMIFS(AT:AT,AM:AM,AM18)-AO18)) | AV18: 96 | AW18: 1.021 | AX18: =AN18-AP18
A19: M & S - T61 (KPK) | G19: =AU19 | I19: SJ 95% BCI Cmd Cmpt CTN 5% Inv Ly 140gsm CW61” | J19: Ivory 80762 | K19: =P19/3 | L19: 0 | M19: =L19 | N19: =M19-L19 | P19: =N19+O19 | Q19: 457136 | R19: Solid | S19: 46321 | U19: 46321 | Y19: 46321 | AJ19: 457136 | AK19: IVORY 80762 | AL19: 140 | AM19: =TRIM(AJ19)&TRIM(AL19)&TRIM(AK19) | AN19: 600 | AO19: -16.3 | AP19: =SUMIFS(M:M,AM:AM,AM19)+SUMIFS(O:O,AM:AM,AM19) | AQ19: =SUMIFS(L:L,AM:AM,AM19) | AR19: =AQ19-AP19 | AS19: =IF(AN19>=AQ19,"ok","ck") | AT19: =-P19 | AU19: =IF(SUMIFS(AT:AT,AM:AM,AM19)>AO19,(SUMIFS(AT:AT,AM:AM,AM19)-AO19)) | AV19: 600 | AW19: 1.028 | AX19: =AN19-AP19
A20: LIDL | G20: =AU20 | I20: KNIT SINGLE JERSEY CMIA COTTON 95% ELASTANE CRERORA 5% GSM-160 CW-167.6 CM/66 INCH | J20: White | K20: =P20/3 | L20: -332.527 | M20: =L20 | N20: =M20-L20 | P20: =N20+O20 | Q20: 440400 | R20: Solid | S20: 46320 | U20: 46320 | Y20: 46320 | AJ20: 440400#Style-2604 (MENS)-Creora | AK20: White | AL20: 160 | AM20: =TRIM(AJ20)&TRIM(AL20)&TRIM(AK20) | AN20: 70760.04 | AO20: -2548.43 | AP20: =SUMIFS(M:M,AM:AM,AM20)+SUMIFS(O:O,AM:AM,AM20) | AQ20: =SUMIFS(L:L,AM:AM,AM20) | AR20: =AQ20-AP20 | AS20: =IF(AN20>=AQ20,"ok","ck") | AT20: =-P20 | AU20: =IF(SUMIFS(AT:AT,AM:AM,AM20)>AO20,(SUMIFS(AT:AT,AM:AM,AM20)-AO20)) | AV20: 35101.78 | AW20: 1.029 | AX20: =AN20-AP20
A21: Sainsbury | G21: =AU21 | I21: S/J- Solid 95%Cot 5%Inv Lycra 140gsm with PCF 66 | J21: Black | K21: =P21/3 | L21: 364.378 | N21: =M21-L21 | P21: =N21+O21 | Q21: 446252 | R21: Solid | S21: 46325 | U21: 46325 | Y21: 46337 | AJ21: 446252 | AK21: Black | AL21: 140 | AM21: =TRIM(AJ21)&TRIM(AL21)&TRIM(AK21) | AN21: 16424.84 | AO21: 2141.13 | AP21: =SUMIFS(M:M,AM:AM,AM21)+SUMIFS(O:O,AM:AM,AM21) | AQ21: =SUMIFS(L:L,AM:AM,AM21) | AR21: =AQ21-AP21 | AS21: =IF(AN21>=AQ21,"ok","ck") | AT21: =-P21 | AU21: =IF(SUMIFS(AT:AT,AM:AM,AM21)>AO21,(SUMIFS(AT:AT,AM:AM,AM21)-AO21)) | AV21: 317 | AW21: 0.744 | AX21: =AN21-AP21
A22: Sainsbury | G22: =AU22 | I22: S/J- Solid 95%Cot 5%Inv Lycra 140gsm with PCF 66 | J22: Black | K22: =P22/3 | L22: 0.082 | N22: =M22-L22 | P22: =N22+O22 | Q22: 446252 | R22: Solid | S22: 46325 | U22: 46325 | Y22: 46341 | AJ22: 446252 | AK22: Black | AL22: 140 | AM22: =TRIM(AJ22)&TRIM(AL22)&TRIM(AK22) | AN22: 16424.84 | AO22: 2141.13 | AP22: =SUMIFS(M:M,AM:AM,AM22)+SUMIFS(O:O,AM:AM,AM22) | AQ22: =SUMIFS(L:L,AM:AM,AM22) | AR22: =AQ22-AP22 | AS22: =IF(AN22>=AQ22,"ok","ck") | AT22: =-P22 | AU22: =IF(SUMIFS(AT:AT,AM:AM,AM22)>AO22,(SUMIFS(AT:AT,AM:AM,AM22)-AO22)) | AV22: 317 | AW22: 0.744 | AX22: =AN22-AP22
A23: Sainsbury | G23: =AU23 | I23: S/J- Solid 95%Cot 5%Inv Lycra 140gsm with PCF 66 | J23: Nude | K23: =P23/3 | L23: -9.554 | M23: =L23 | N23: =M23-L23 | P23: =N23+O23 | Q23: 446252 | R23: Solid | S23: 46320 | U23: 46320 | Y23: 46320 | AJ23: 446252 | AK23: NUDE | AL23: 140 | AM23: =TRIM(AJ23)&TRIM(AL23)&TRIM(AK23) | AN23: 2601 | AO23: -61 | AP23: =SUMIFS(M:M,AM:AM,AM23)+SUMIFS(O:O,AM:AM,AM23) | AQ23: =SUMIFS(L:L,AM:AM,AM23) | AR23: =AQ23-AP23 | AS23: =IF(AN23>=AQ23,"ok","ck") | AT23: =-P23 | AU23: =IF(SUMIFS(AT:AT,AM:AM,AM23)>AO23,(SUMIFS(AT:AT,AM:AM,AM23)-AO23)) | AV23: 2601 | AW23: 1.024 | AX23: =AN23-AP23
A24: LIDL | G24: =AU24 | I24: 48% LYOCELL 47% CMIA COTTON 5% ELASTANE RIB 2X2 GSM-190 CW-111 CM/44 INCH | J24: Black | K24: =P24/3 | L24: 0 | N24: =M24-L24 | P24: =N24+O24 | Q24: 438197 | R24: Solid | S24: 46331 | U24: 46331 | Y24: 46331 | AJ24: 438197#Style-2604 (MENS)-Creora | AK24: Black | AL24: 190 | AM24: =TRIM(AJ24)&TRIM(AL24)&TRIM(AK24) | AN24: 77382.29 | AO24: 1396.71 | AP24: =SUMIFS(M:M,AM:AM,AM24)+SUMIFS(O:O,AM:AM,AM24) | AQ24: =SUMIFS(L:L,AM:AM,AM24) | AR24: =AQ24-AP24 | AS24: =IF(AN24>=AQ24,"ok","ck") | AT24: =-P24 | AU24: =IF(SUMIFS(AT:AT,AM:AM,AM24)>AO24,(SUMIFS(AT:AT,AM:AM,AM24)-AO24)) | AV24: 9721.87 | AW24: 0.914 | AX24: =AN24-AP24
A25: M & S - T61 (KPK) | G25: =AU25 | I25: SJ 100% BCI Combed Compact Cotton 120gsm CW62” | J25: White AOP Gusset 10001 | K25: =P25/3 | L25: 4.95 | M25: =L25 | N25: =M25-L25 | P25: =N25+O25 | Q25: 441109 | R25: Solid | S25: 46320 | U25: 46320 | Y25: 46320 | AJ25: 441109 | AK25: WHITE 10001 AOP-G | AL25: 120 | AM25: =TRIM(AJ25)&TRIM(AL25)&TRIM(AK25) | AN25: 666 | AO25: -13 | AP25: =SUMIFS(M:M,AM:AM,AM25)+SUMIFS(O:O,AM:AM,AM25) | AQ25: =SUMIFS(L:L,AM:AM,AM25) | AR25: =AQ25-AP25 | AS25: =IF(AN25>=AQ25,"ok","ck") | AT25: =-P25 | AU25: =IF(SUMIFS(AT:AT,AM:AM,AM25)>AO25,(SUMIFS(AT:AT,AM:AM,AM25)-AO25)) | AV25: 666 | AW25: 1.02 | AX25: =AN25-AP25
A26: LIDL | G26: =AU26 | I26: 48% LYOCELL 47% CMIA COTTON 5% ELASTANE RIB 2X2 GSM-190 CW-111 CM/44 INCH | J26: Black | K26: =P26/3 | L26: 0 | N26: =M26-L26 | P26: =N26+O26 | Q26: 438197 | R26: Solid | S26: 46328 | U26: 46328 | Y26: 46328 | AJ26: 438197#Style-2604 (MENS)-Creora | AK26: Black | AL26: 190 | AM26: =TRIM(AJ26)&TRIM(AL26)&TRIM(AK26) | AN26: 77382.29 | AO26: 1396.71 | AP26: =SUMIFS(M:M,AM:AM,AM26)+SUMIFS(O:O,AM:AM,AM26) | AQ26: =SUMIFS(L:L,AM:AM,AM26) | AR26: =AQ26-AP26 | AS26: =IF(AN26>=AQ26,"ok","ck") | AT26: =-P26 | AU26: =IF(SUMIFS(AT:AT,AM:AM,AM26)>AO26,(SUMIFS(AT:AT,AM:AM,AM26)-AO26)) | AV26: 9721.87 | AW26: 0.914 | AX26: =AN26-AP26
A27: M & S - T61 (KPK) | G27: =AU27 | I27: SJ 100% BCI Combed Compact Cotton 120gsm CW62” | J27: Light Cream 81001 | K27: =P27/3 | L27: 0.154 | N27: =M27-L27 | P27: =N27+O27 | Q27: 466842 | R27: Solid | S27: 46345 | U27: 46345 | Y27: 46345 | AJ27: 466842 | AK27: Light Cream 81001 | AL27: 120 | AM27: =TRIM(AJ27)&TRIM(AL27)&TRIM(AK27) | AN27: 0 | AO27: #NA | AP27: =SUMIFS(M:M,AM:AM,AM27)+SUMIFS(O:O,AM:AM,AM27) | AQ27: =SUMIFS(L:L,AM:AM,AM27) | AR27: =AQ27-AP27 | AS27: =IF(AN27>=AQ27,"ok","ck") | AT27: =-P27 | AU27: =IF(SUMIFS(AT:AT,AM:AM,AM27)>AO27,(SUMIFS(AT:AT,AM:AM,AM27)-AO27)) | AV27: 0 | AW27: 0 | AX27: =AN27-AP27
A28: M & S - T61 (KPK) | G28: =AU28 | I28: SJ 100% BCI Combed Compact Cotton 120gsm CW62” | J28: Light Cream 81001 | K28: =P28/3 | L28: 34.44 | N28: =M28-L28 | P28: =N28+O28 | Q28: 466842 | R28: Solid | S28: 46335 | U28: 46335 | Y28: 46337 | AJ28: 466842 | AK28: Light Cream 81001 | AL28: 120 | AM28: =TRIM(AJ28)&TRIM(AL28)&TRIM(AK28) | AN28: 0 | AO28: #NA | AP28: =SUMIFS(M:M,AM:AM,AM28)+SUMIFS(O:O,AM:AM,AM28) | AQ28: =SUMIFS(L:L,AM:AM,AM28) | AR28: =AQ28-AP28 | AS28: =IF(AN28>=AQ28,"ok","ck") | AT28: =-P28 | AU28: =IF(SUMIFS(AT:AT,AM:AM,AM28)>AO28,(SUMIFS(AT:AT,AM:AM,AM28)-AO28)) | AV28: 0 | AW28: 0 | AX28: =AN28-AP28
A29: Sainsbury | G29: =AU29 | I29: S/J Gusset 100% Cotton 110gsm CW64 | J29: TU WHITE 25 | K29: =P29/3 | L29: 2.5 | N29: =M29-L29 | P29: =N29+O29 | Q29: 467667 | R29: Solid | S29: 46340 | U29: 46340 | Y29: 46337 | AJ29: 467667 | AK29: TU White 25 | AL29: 110 | AM29: =TRIM(AJ29)&TRIM(AL29)&TRIM(AK29) | AN29: 0 | AO29: #NA | AP29: =SUMIFS(M:M,AM:AM,AM29)+SUMIFS(O:O,AM:AM,AM29) | AQ29: =SUMIFS(L:L,AM:AM,AM29) | AR29: =AQ29-AP29 | AS29: =IF(AN29>=AQ29,"ok","ck") | AT29: =-P29 | AU29: =IF(SUMIFS(AT:AT,AM:AM,AM29)>AO29,(SUMIFS(AT:AT,AM:AM,AM29)-AO29)) | AV29: 0 | AW29: 0 | AX29: =AN29-AP29
A30: Sainsbury | G30: =AU30 | I30: S/J Gusset 100% Cotton 110gsm CW64 | J30: TU WHITE 25 | K30: =P30/3 | L30: 3.281 | N30: =M30-L30 | P30: =N30+O30 | Q30: 467667 | R30: Solid | S30: 46340 | U30: 46340 | Y30: 46340 | AJ30: 467667 | AK30: TU White 25 | AL30: 110 | AM30: =TRIM(AJ30)&TRIM(AL30)&TRIM(AK30) | AN30: 0 | AO30: #NA | AP30: =SUMIFS(M:M,AM:AM,AM30)+SUMIFS(O:O,AM:AM,AM30) | AQ30: =SUMIFS(L:L,AM:AM,AM30) | AR30: =AQ30-AP30 | AS30: =IF(AN30>=AQ30,"ok","ck") | AT30: =-P30 | AU30: =IF(SUMIFS(AT:AT,AM:AM,AM30)>AO30,(SUMIFS(AT:AT,AM:AM,AM30)-AO30)) | AV30: 0 | AW30: 0 | AX30: =AN30-AP30
A31: T61-KPK | G31: =AU31 | I31: SJ 100% BCI Combed Compact Cotton 120gsm CW62” | J31: White 10001 | K31: =P31/3 | L31: 120.514 | M31: 120.514 | N31: =M31-L31 | P31: =N31+O31 | R31: Solid | S31: 46327 | U31: 1st Nov-10th Nov-1.5k mtr/day, 11th Nov-25th Nov- 2.5k mtr, FOC will deliver on 26th Nov | Y31: 46320 | AL31: 120 | AM31: =TRIM(AJ31)&TRIM(AL31)&TRIM(AK31) | AN31: 0 | AO31: #NA | AP31: =SUMIFS(M:M,AM:AM,AM31)+SUMIFS(O:O,AM:AM,AM31) | AQ31: =SUMIFS(L:L,AM:AM,AM31) | AR31: =AQ31-AP31 | AS31: =IF(AN31>=AQ31,"ok","ck") | AT31: =-P31 | AU31: =IF(SUMIFS(AT:AT,AM:AM,AM31)>AO31,(SUMIFS(AT:AT,AM:AM,AM31)-AO31)) | AV31: #N/A | AW31: #N/A | AX31: =AN31-AP31
A32: M & S - T61 (KPK) | G32: =AU32 | I32: SJ 95% BCI Cmd Cmpt CTN 5% Inv Ly 140gsm CW61” | J32: 62551 PINK | K32: =P32/3 | L32: 27.61 | N32: =M32-L32 | P32: =N32+O32 | Q32: 464904 | R32: Solid | S32: 46320 | U32: 46320 | Y32: 46320 | AJ32: 464904 | AK32: 62551 Pink | AL32: 140 | AM32: =TRIM(AJ32)&TRIM(AL32)&TRIM(AK32) | AN32: 526 | AO32: 28 | AP32: =SUMIFS(M:M,AM:AM,AM32)+SUMIFS(O:O,AM:AM,AM32) | AQ32: =SUMIFS(L:L,AM:AM,AM32) | AR32: =AQ32-AP32 | AS32: =IF(AN32>=AQ32,"ok","ck") | AT32: =-P32 | AU32: =IF(SUMIFS(AT:AT,AM:AM,AM32)>AO32,(SUMIFS(AT:AT,AM:AM,AM32)-AO32)) | AV32: 526 | AW32: 0.949 | AX32: =AN32-AP32
A33: M & S - T51 | G33: =AU33 | I33: SJ 95% BCI Cmd Cmpt CTN 5% Inv Ly 140gsm CW61” | J33: DARK NAVY 33016 | K33: =P33/3 | L33: 0 | M33: =L33 | N33: =M33-L33 | P33: =N33+O33 | Q33: 465410 | R33: Solid | S33: 46321 | U33: 46321 | Y33: 46321 | AJ33: 465410 | AK33: Dark Navy 33016 | AL33: 140 | AM33: =TRIM(AJ33)&TRIM(AL33)&TRIM(AK33) | AN33: 381.01 | AO33: 13.97 | AP33: =SUMIFS(M:M,AM:AM,AM33)+SUMIFS(O:O,AM:AM,AM33) | AQ33: =SUMIFS(L:L,AM:AM,AM33) | AR33: =AQ33-AP33 | AS33: =IF(AN33>=AQ33,"ok","ck") | AT33: =-P33 | AU33: =IF(SUMIFS(AT:AT,AM:AM,AM33)>AO33,(SUMIFS(AT:AT,AM:AM,AM33)-AO33)) | AV33: 381.01 | AW33: 0.965 | AX33: =AN33-AP33
A34: M & S - T51 | G34: =AU34 | I34: SJ 95% BCI Cmd Cmpt CTN 5% Inv Ly 140gsm CW61” | J34: DARK NAVY 33016 | K34: =P34/3 | L34: 14 | M34: =L34 | N34: =M34-L34 | P34: =N34+O34 | Q34: 465410 | R34: Solid | S34: 46331 | U34: 46331 | Y34: 46323 | AJ34: 465410 | AK34: Dark Navy 33016 | AL34: 140 | AM34: =TRIM(AJ34)&TRIM(AL34)&TRIM(AK34) | AN34: 381.01 | AO34: 13.97 | AP34: =SUMIFS(M:M,AM:AM,AM34)+SUMIFS(O:O,AM:AM,AM34) | AQ34: =SUMIFS(L:L,AM:AM,AM34) | AR34: =AQ34-AP34 | AS34: =IF(AN34>=AQ34,"ok","ck") | AT34: =-P34 | AU34: =IF(SUMIFS(AT:AT,AM:AM,AM34)>AO34,(SUMIFS(AT:AT,AM:AM,AM34)-AO34)) | AV34: 381.01 | AW34: 0.965 | AX34: =AN34-AP34
A35: M & S - T51 | G35: =AU35 | I35: SJ 95% BCI Cmd Cmpt CTN 5% Inv Ly 140gsm CW61” | J35: DARK NAVY 33016 | K35: =P35/3 | L35: 0 | M35: =L35 | N35: =M35-L35 | P35: =N35+O35 | Q35: 465410 | R35: Solid | S35: 46321 | U35: 46321 | Y35: 46321 | AJ35: 465410 | AK35: Dark Navy 33016 | AL35: 140 | AM35: =TRIM(AJ35)&TRIM(AL35)&TRIM(AK35) | AN35: 381.01 | AO35: 13.97 | AP35: =SUMIFS(M:M,AM:AM,AM35)+SUMIFS(O:O,AM:AM,AM35) | AQ35: =SUMIFS(L:L,AM:AM,AM35) | AR35: =AQ35-AP35 | AS35: =IF(AN35>=AQ35,"ok","ck") | AT35: =-P35 | AU35: =IF(SUMIFS(AT:AT,AM:AM,AM35)>AO35,(SUMIFS(AT:AT,AM:AM,AM35)-AO35)) | AV35: 381.01 | AW35: 0.965 | AX35: =AN35-AP35
A36: LIDL | G36: =AU36 | I36: 48% LYOCELL 47% CMIA COTTON 5% ELASTANE RIB 2X2 GSM-190 CW-111 CM/44 INCH | J36: Coronet Blue | K36: =P36/3 | L36: 0 | N36: =M36-L36 | P36: =N36+O36 | Q36: 438197 | R36: Solid | S36: 46320 | U36: 46320 | Y36: 46320 | AJ36: 438197#Style-2604 (MENS)-Creora | AK36: Coronet Blue 18-3922 Tcx | AL36: 190 | AM36: =TRIM(AJ36)&TRIM(AL36)&TRIM(AK36) | AN36: 54271.64 | AO36: 3151.36 | AP36: =SUMIFS(M:M,AM:AM,AM36)+SUMIFS(O:O,AM:AM,AM36) | AQ36: =SUMIFS(L:L,AM:AM,AM36) | AR36: =AQ36-AP36 | AS36: =IF(AN36>=AQ36,"ok","ck") | AT36: =-P36 | AU36: =IF(SUMIFS(AT:AT,AM:AM,AM36)>AO36,(SUMIFS(AT:AT,AM:AM,AM36)-AO36)) | AV36: 56 | AW36: 0.093 | AX36: =AN36-AP36
A37: LIDL | G37: =AU37 | I37: 48% LYOCELL 47% CMIA COTTON 5% ELASTANE RIB 2X2 GSM-190 CW-111 CM/44 INCH | J37: Coronet Blue | K37: =P37/3 | L37: 0 | N37: =M37-L37 | P37: =N37+O37 | Q37: 438197 | R37: Solid | S37: 46320 | U37: 46320 | Y37: 46320 | AJ37: 438197#Style-2604 (MENS)-Creora | AK37: Coronet Blue 18-3922 Tcx | AL37: 190 | AM37: =TRIM(AJ37)&TRIM(AL37)&TRIM(AK37) | AN37: 54271.64 | AO37: 3151.36 | AP37: =SUMIFS(M:M,AM:AM,AM37)+SUMIFS(O:O,AM:AM,AM37) | AQ37: =SUMIFS(L:L,AM:AM,AM37) | AR37: =AQ37-AP37 | AS37: =IF(AN37>=AQ37,"ok","ck") | AT37: =-P37 | AU37: =IF(SUMIFS(AT:AT,AM:AM,AM37)>AO37,(SUMIFS(AT:AT,AM:AM,AM37)-AO37)) | AV37: 56 | AW37: 0.093 | AX37: =AN37-AP37
A38: LIDL | G38: =AU38 | I38: 48% LYOCELL 47% CMIA COTTON 5% ELASTANE RIB 2X2 GSM-190 CW-111 CM/44 INCH | J38: Coronet Blue | K38: =P38/3 | L38: 0 | N38: =M38-L38 | P38: =N38+O38 | Q38: 438197 | R38: Solid | S38: 46320 | U38: 46320 | Y38: 46320 | AJ38: 438197#Style-2604 (MENS)-Creora | AK38: Coronet Blue 18-3922 Tcx | AL38: 190 | AM38: =TRIM(AJ38)&TRIM(AL38)&TRIM(AK38) | AN38: 54271.64 | AO38: 3151.36 | AP38: =SUMIFS(M:M,AM:AM,AM38)+SUMIFS(O:O,AM:AM,AM38) | AQ38: =SUMIFS(L:L,AM:AM,AM38) | AR38: =AQ38-AP38 | AS38: =IF(AN38>=AQ38,"ok","ck") | AT38: =-P38 | AU38: =IF(SUMIFS(AT:AT,AM:AM,AM38)>AO38,(SUMIFS(AT:AT,AM:AM,AM38)-AO38)) | AV38: 56 | AW38: 0.093 | AX38: =AN38-AP38
A39: LIDL | G39: =AU39 | I39: 48% LYOCELL 47% CMIA COTTON 5% ELASTANE RIB 2X2 GSM-190 CW-111 CM/44 INCH | J39: Coronet Blue | K39: =P39/3 | L39: 0 | N39: =M39-L39 | P39: =N39+O39 | Q39: 438197 | R39: Solid | S39: 46331 | U39: 46331 | Y39: 46331 | AJ39: 438197#Style-2604 (MENS)-Creora | AK39: Coronet Blue 18-3922 Tcx | AL39: 190 | AM39: =TRIM(AJ39)&TRIM(AL39)&TRIM(AK39) | AN39: 54271.64 | AO39: 3151.36 | AP39: =SUMIFS(M:M,AM:AM,AM39)+SUMIFS(O:O,AM:AM,AM39) | AQ39: =SUMIFS(L:L,AM:AM,AM39) | AR39: =AQ39-AP39 | AS39: =IF(AN39>=AQ39,"ok","ck") | AT39: =-P39 | AU39: =IF(SUMIFS(AT:AT,AM:AM,AM39)>AO39,(SUMIFS(AT:AT,AM:AM,AM39)-AO39)) | AV39: 56 | AW39: 0.093 | AX39: =AN39-AP39
A40: LIDL | G40: =AU40 | I40: 48% LYOCELL 47% CMIA COTTON 5% ELASTANE RIB 2X2 GSM-190 CW-111 CM/44 INCH | J40: Coronet Blue | K40: =P40/3 | L40: 0 | N40: =M40-L40 | P40: =N40+O40 | Q40: 438197 | R40: Solid | S40: 46340 | U40: 46340 | Y40: 46340 | AJ40: 438197#Style-2604 (MENS)-Creora | AK40: Coronet Blue 18-3922 Tcx | AL40: 190 | AM40: =TRIM(AJ40)&TRIM(AL40)&TRIM(AK40) | AN40: 54271.64 | AO40: 3151.36 | AP40: =SUMIFS(M:M,AM:AM,AM40)+SUMIFS(O:O,AM:AM,AM40) | AQ40: =SUMIFS(L:L,AM:AM,AM40) | AR40: =AQ40-AP40 | AS40: =IF(AN40>=AQ40,"ok","ck") | AT40: =-P40 | AU40: =IF(SUMIFS(AT:AT,AM:AM,AM40)>AO40,(SUMIFS(AT:AT,AM:AM,AM40)-AO40)) | AV40: 56 | AW40: 0.093 | AX40: =AN40-AP40
...

Sheet Date Wise Pivot -Hues
A1: SQ Biricina · Hues Date-wise RFD Status
A2: Agreed RFD Date (Hues) vs Required / RFD quantity — Oct'26 Fabric Plan
B4: Values | G4: Achievement %
A5: Agreed RFD Date-Hues | B5: Req Qty(Mtr) | C5: RFD Qty. | D5: Balance to RFD | E5: Recovered Qty | F5: Final Balance | G5: =IFERROR(C5/B5,"")
A6: 46296 | B6: 35895.565 | C6: 35128.563 | D6: -767.002 | F6: -767.002 | G6: =IFERROR(C6/B6,"") -> 0.9786324
A7: 46297 | B7: 29183.722 | C7: 29183.722 | D7: 0 | F7: 0 | G7: =IFERROR(C7/B7,"") -> 1
A8: 46298 | B8: 40859.232 | C8: 40369.292 | D8: -489.94 | F8: -489.94 | G8: =IFERROR(C8/B8,"") -> 0.98800907
A9: 46299 | B9: 74983.186 | C9: 72636.546 | D9: -2346.64 | F9: -2346.64 | G9: =IFERROR(C9/B9,"") -> 0.96870445
A10: 46300 | B10: 49807.677 | C10: 49443.964 | D10: -363.713 | F10: -363.713 | G10: =IFERROR(C10/B10,"") -> 0.99269765
A11: 46301 | B11: 20835.634 | C11: 20716.874 | D11: -118.76 | F11: -118.76 | G11: =IFERROR(C11/B11,"") -> 0.99430015
A12: 46302 | B12: 45186.572 | C12: 44162.392 | D12: -1024.18 | F12: -1024.18 | G12: =IFERROR(C12/B12,"") -> 0.97733442
A13: 46303 | B13: 21927.651 | C13: 20615.89 | D13: -1311.761 | F13: -1311.761 | G13: =IFERROR(C13/B13,"") -> 0.94017777
A14: 46304 | B14: 25175.1 | C14: 25174.888 | D14: -0.212 | F14: -0.212 | G14: =IFERROR(C14/B14,"") -> 0.99999158
A15: 46305 | B15: 54032.272 | C15: 35099.636 | D15: -18932.636 | F15: -18932.636 | G15: =IFERROR(C15/B15,"") -> 0.64960504
A16: 46306 | B16: 43780.515 | C16: 42213.655 | D16: -1566.86 | F16: -1566.86 | G16: =IFERROR(C16/B16,"") -> 0.96421102
A17: 46307 | B17: 24063.957 | C17: 20445.178 | D17: -3618.779 | F17: -3618.779 | G17: =IFERROR(C17/B17,"") -> 0.84961829
... A45: 46335 | B45: 20570.094 | C45: 2250.52 | D45: -18319.574 | F45: -18319.574 | G45: =IFERROR(C45/B45,"") -> 0.10940738
A46: 46336 | B46: 22053.114 | D46: -22053.114 | F46: -22053.114 | G46: =IFERROR(C46/B46,"") -> 0
A47: 46337 | B47: 8000 | D47: -8000 | F47: -8000 | G47: =IFERROR(C47/B47,"") -> 0
A48: 46338 | B48: 6670 | D48: -6670 | F48: -6670 | G48: =IFERROR(C48/B48,"") -> 0
A49: 46339 | B49: 5000 | D49: -5000 | F49: -5000 | G49: =IFERROR(C49/B49,"") -> 0
A50: 46340 | B50: 10366 | D50: -10366 | F50: -10366 | G50: =IFERROR(C50/B50,"") -> 0
A51: 46341 | B51: 5000 | D51: -5000 | F51: -5000 | G51: =IFERROR(C51/B51,"") -> 0
A52: 46342 | B52: 5000 | D52: -5000 | F52: -5000 | G52: =IFERROR(C52/B52,"") -> 0
A53: 46343 | B53: 5000 | D53: -5000 | F53: -5000 | G53: =IFERROR(C53/B53,"") -> 0
A54: 46344 | B54: 5000 | D54: -5000 | F54: -5000 | G54: =IFERROR(C54/B54,"") -> 0
A55: 46345 | B55: 5000 | D55: -5000 | F55: -5000 | G55: =IFERROR(C55/B55,"") -> 0
A56: 46346 | B56: 5000 | D56: -5000 | F56: -5000 | G56: =IFERROR(C56/B56,"") -> 0
A57: 46347 | B57: 5000 | D57: -5000 | F57: -5000 | G57: =IFERROR(C57/B57,"") -> 0
... A61: 46351 | B61: 47651 | D61: -47651 | F61: -47651 | G61: =IFERROR(C61/B61,"") -> 0
A62: (blank) | G62: =IFERROR(C62/B62,"")
A63: Grand Total | B63: 1646166.5 | C63: 777417.37 | D63: -868749.15 | F63: -868749.15 | G63: =IFERROR(C63/B63,"") -> 0.47225925
